<?xml version="1.0" encoding="UTF-8"?><testsuite name="nosetests" tests="29" errors="0" failures="9" skip="0"><testcase classname="test_items.TestItems" name="test_add_an_item" time="0.108"></testcase><testcase classname="test_items.TestItems" name="test_create_an_item" time="0.034"></testcase><testcase classname="test_items.TestItems" name="test_delete_an_item" time="0.039"></testcase><testcase classname="test_items.TestItems" name="test_deserialize_an_item" time="0.020"></testcase><testcase classname="test_items.TestItems" name="test_find_by_availability" time="0.048"></testcase><testcase classname="test_items.TestItems" name="test_find_by_brand" time="0.044"></testcase><testcase classname="test_items.TestItems" name="test_find_by_name" time="0.045"></testcase><testcase classname="test_items.TestItems" name="test_find_by_price" time="0.049"></testcase><testcase classname="test_items.TestItems" name="test_find_by_sku" time="0.047"></testcase><testcase classname="test_items.TestItems" name="test_find_item" time="0.046"></testcase><testcase classname="test_items.TestItems" name="test_find_or_404" time="0.048"></testcase><testcase classname="test_items.TestItems" name="test_serialize_an_item" time="0.018"></testcase><testcase classname="test_items.TestItems" name="test_update_an_item" time="0.050"></testcase><testcase classname="test_server.TestItemServer" name="test_call_create_with_an_id" time="0.070"></testcase><testcase classname="test_server.TestItemServer" name="test_create_item" time="0.044"><failure type="exceptions.AssertionError" message="500 != 201&#10;-------------------- &gt;&gt; begin captured stdout &lt;&lt; ---------------------&#10;&lt;Response streamed [500 INTERNAL SERVER ERROR]&gt;&#10;&#10;--------------------- &gt;&gt; end captured stdout &lt;&lt; ----------------------"><![CDATA[  File "/usr/lib/python2.7/unittest/case.py", line 329, in run
    testMethod()
  File "/vagrant/tests/test_server.py", line 107, in test_create_item
    self.assertEqual(resp.status_code, status.HTTP_201_CREATED)
  File "/usr/lib/python2.7/unittest/case.py", line 513, in assertEqual
    assertion_func(first, second, msg=msg)
  File "/usr/lib/python2.7/unittest/case.py", line 506, in _baseAssertEqual
    raise self.failureException(msg)
500 != 201
-------------------- >> begin captured stdout << ---------------------
<Response streamed [500 INTERNAL SERVER ERROR]>

--------------------- >> end captured stdout << ----------------------]]></failure><system-out><![CDATA[<Response streamed [500 INTERNAL SERVER ERROR]>
]]></system-out></testcase><testcase classname="test_server.TestItemServer" name="test_create_item_no_content_type" time="0.038"><failure type="exceptions.AssertionError" message="500 != 415"><![CDATA[Traceback (most recent call last):
  File "/usr/lib/python2.7/unittest/case.py", line 329, in run
    testMethod()
  File "/vagrant/tests/test_server.py", line 204, in test_create_item_no_content_type
    self.assertEqual(resp.status_code, status.HTTP_415_UNSUPPORTED_MEDIA_TYPE)
  File "/usr/lib/python2.7/unittest/case.py", line 513, in assertEqual
    assertion_func(first, second, msg=msg)
  File "/usr/lib/python2.7/unittest/case.py", line 506, in _baseAssertEqual
    raise self.failureException(msg)
AssertionError: 500 != 415
]]></failure></testcase><testcase classname="test_server.TestItemServer" name="test_create_item_with_no_name" time="0.038"><failure type="exceptions.AssertionError" message="500 != 400"><![CDATA[Traceback (most recent call last):
  File "/usr/lib/python2.7/unittest/case.py", line 329, in run
    testMethod()
  File "/vagrant/tests/test_server.py", line 197, in test_create_item_with_no_name
    self.assertEqual(resp.status_code, status.HTTP_400_BAD_REQUEST)
  File "/usr/lib/python2.7/unittest/case.py", line 513, in assertEqual
    assertion_func(first, second, msg=msg)
  File "/usr/lib/python2.7/unittest/case.py", line 506, in _baseAssertEqual
    raise self.failureException(msg)
AssertionError: 500 != 400
]]></failure></testcase><testcase classname="test_server.TestItemServer" name="test_delete_item" time="0.066"></testcase><testcase classname="test_server.TestItemServer" name="test_get_item" time="0.054"></testcase><testcase classname="test_server.TestItemServer" name="test_get_item_list" time="0.050"></testcase><testcase classname="test_server.TestItemServer" name="test_get_item_not_found" time="0.039"><failure type="exceptions.AssertionError" message="500 != 404"><![CDATA[Traceback (most recent call last):
  File "/usr/lib/python2.7/unittest/case.py", line 329, in run
    testMethod()
  File "/vagrant/tests/test_server.py", line 95, in test_get_item_not_found
    self.assertEqual(resp.status_code, status.HTTP_404_NOT_FOUND)
  File "/usr/lib/python2.7/unittest/case.py", line 513, in assertEqual
    assertion_func(first, second, msg=msg)
  File "/usr/lib/python2.7/unittest/case.py", line 506, in _baseAssertEqual
    raise self.failureException(msg)
AssertionError: 500 != 404
]]></failure></testcase><testcase classname="test_server.TestItemServer" name="test_get_nonexisting_item" time="0.045"><failure type="exceptions.AssertionError" message="500 != 404"><![CDATA[Traceback (most recent call last):
  File "/usr/lib/python2.7/unittest/case.py", line 329, in run
    testMethod()
  File "/vagrant/tests/test_server.py", line 209, in test_get_nonexisting_item
    self.assertEqual(resp.status_code, status.HTTP_404_NOT_FOUND)
  File "/usr/lib/python2.7/unittest/case.py", line 513, in assertEqual
    assertion_func(first, second, msg=msg)
  File "/usr/lib/python2.7/unittest/case.py", line 506, in _baseAssertEqual
    raise self.failureException(msg)
AssertionError: 500 != 404
]]></failure></testcase><testcase classname="test_server.TestItemServer" name="test_index" time="0.037"><failure type="exceptions.AssertionError" message="404 != 200"><![CDATA[Traceback (most recent call last):
  File "/usr/lib/python2.7/unittest/case.py", line 329, in run
    testMethod()
  File "/vagrant/tests/test_server.py", line 71, in test_index
    self.assertEqual(resp.status_code, status.HTTP_200_OK)
  File "/usr/lib/python2.7/unittest/case.py", line 513, in assertEqual
    assertion_func(first, second, msg=msg)
  File "/usr/lib/python2.7/unittest/case.py", line 506, in _baseAssertEqual
    raise self.failureException(msg)
AssertionError: 404 != 200
]]></failure></testcase><testcase classname="test_server.TestItemServer" name="test_query_item_list_by_brand" time="0.060"></testcase><testcase classname="test_server.TestItemServer" name="test_query_item_list_by_name" time="0.050"></testcase><testcase classname="test_server.TestItemServer" name="test_query_item_list_by_sku" time="0.049"></testcase><testcase classname="test_server.TestItemServer" name="test_update_item" time="0.043"><failure type="exceptions.AssertionError" message="500 != 200"><![CDATA[Traceback (most recent call last):
  File "/usr/lib/python2.7/unittest/case.py", line 329, in run
    testMethod()
  File "/vagrant/tests/test_server.py", line 129, in test_update_item
    self.assertEqual(resp.status_code, status.HTTP_200_OK)
  File "/usr/lib/python2.7/unittest/case.py", line 513, in assertEqual
    assertion_func(first, second, msg=msg)
  File "/usr/lib/python2.7/unittest/case.py", line 506, in _baseAssertEqual
    raise self.failureException(msg)
AssertionError: 500 != 200
]]></failure></testcase><testcase classname="test_server.TestItemServer" name="test_update_item_not_found" time="0.041"><failure type="exceptions.AssertionError" message="500 != 404"><![CDATA[Traceback (most recent call last):
  File "/usr/lib/python2.7/unittest/case.py", line 329, in run
    testMethod()
  File "/vagrant/tests/test_server.py", line 190, in test_update_item_not_found
    self.assertEqual(resp.status_code, status.HTTP_404_NOT_FOUND)
  File "/usr/lib/python2.7/unittest/case.py", line 513, in assertEqual
    assertion_func(first, second, msg=msg)
  File "/usr/lib/python2.7/unittest/case.py", line 506, in _baseAssertEqual
    raise self.failureException(msg)
AssertionError: 500 != 404
]]></failure></testcase><testcase classname="test_server.TestItemServer" name="test_update_item_with_no_name" time="0.039"><failure type="exceptions.AssertionError" message="500 != 400"><![CDATA[Traceback (most recent call last):
  File "/usr/lib/python2.7/unittest/case.py", line 329, in run
    testMethod()
  File "/vagrant/tests/test_server.py", line 183, in test_update_item_with_no_name
    self.assertEqual(resp.status_code, status.HTTP_400_BAD_REQUEST)
  File "/usr/lib/python2.7/unittest/case.py", line 513, in assertEqual
    assertion_func(first, second, msg=msg)
  File "/usr/lib/python2.7/unittest/case.py", line 506, in _baseAssertEqual
    raise self.failureException(msg)
AssertionError: 500 != 400
]]></failure></testcase></testsuite>